[2024-03-26T03:02:29.748+0000] {taskinstance.py:1979} INFO - Dependencies all met for dep_context=non-requeueable deps ti=<TaskInstance: upload_historical_congress_data.member_external_table_task scheduled__2024-03-15T00:00:00+00:00 [queued]>
[2024-03-26T03:02:29.758+0000] {taskinstance.py:1979} INFO - Dependencies all met for dep_context=requeueable deps ti=<TaskInstance: upload_historical_congress_data.member_external_table_task scheduled__2024-03-15T00:00:00+00:00 [queued]>
[2024-03-26T03:02:29.760+0000] {taskinstance.py:2193} INFO - Starting attempt 2 of 3
[2024-03-26T03:02:29.768+0000] {taskinstance.py:2217} INFO - Executing <Task(BigQueryCreateExternalTableOperator): member_external_table_task> on 2024-03-15 00:00:00+00:00
[2024-03-26T03:02:29.776+0000] {standard_task_runner.py:60} INFO - Started process 80 to run task
[2024-03-26T03:02:29.779+0000] {standard_task_runner.py:87} INFO - Running: ['***', 'tasks', 'run', 'upload_historical_congress_data', 'member_external_table_task', 'scheduled__2024-03-15T00:00:00+00:00', '--job-id', '81', '--raw', '--subdir', 'DAGS_FOLDER/upload_historical_congress_data.py', '--cfg-path', '/tmp/tmpvwa28337']
[2024-03-26T03:02:29.784+0000] {standard_task_runner.py:88} INFO - Job 81: Subtask member_external_table_task
[2024-03-26T03:02:29.844+0000] {task_command.py:423} INFO - Running <TaskInstance: upload_historical_congress_data.member_external_table_task scheduled__2024-03-15T00:00:00+00:00 [running]> on host 4fee77e26a47
[2024-03-26T03:02:29.898+0000] {taskinstance.py:2513} INFO - Exporting env vars: AIRFLOW_CTX_DAG_EMAIL='***@***.com' AIRFLOW_CTX_DAG_OWNER='***' AIRFLOW_CTX_DAG_ID='upload_historical_congress_data' AIRFLOW_CTX_TASK_ID='member_external_table_task' AIRFLOW_CTX_EXECUTION_DATE='2024-03-15T00:00:00+00:00' AIRFLOW_CTX_TRY_NUMBER='2' AIRFLOW_CTX_DAG_RUN_ID='scheduled__2024-03-15T00:00:00+00:00'
[2024-03-26T03:02:29.915+0000] {taskinstance.py:2731} ERROR - Task failed with exception
Traceback (most recent call last):
  File "/home/airflow/.local/lib/python3.8/site-packages/airflow/models/taskinstance.py", line 444, in _execute_task
    result = _execute_callable(context=context, **execute_callable_kwargs)
  File "/home/airflow/.local/lib/python3.8/site-packages/airflow/models/taskinstance.py", line 414, in _execute_callable
    return execute_callable(context=context, **execute_callable_kwargs)
  File "/home/airflow/.local/lib/python3.8/site-packages/airflow/providers/google/cloud/operators/bigquery.py", line 1777, in execute
    bq_hook = BigQueryHook(
  File "/home/airflow/.local/lib/python3.8/site-packages/airflow/providers/google/cloud/hooks/bigquery.py", line 119, in __init__
    super().__init__(
  File "/home/airflow/.local/lib/python3.8/site-packages/airflow/providers/google/common/hooks/base_google.py", line 251, in __init__
    self.extras: dict = self.get_connection(self.gcp_conn_id).extra_dejson
  File "/home/airflow/.local/lib/python3.8/site-packages/airflow/hooks/base.py", line 82, in get_connection
    conn = Connection.get_connection_from_secrets(conn_id)
  File "/home/airflow/.local/lib/python3.8/site-packages/airflow/models/connection.py", line 514, in get_connection_from_secrets
    raise AirflowNotFoundException(f"The conn_id `{conn_id}` isn't defined")
airflow.exceptions.AirflowNotFoundException: The conn_id `google_cloud_default` isn't defined
[2024-03-26T03:02:29.921+0000] {taskinstance.py:1149} INFO - Marking task as UP_FOR_RETRY. dag_id=upload_historical_congress_data, task_id=member_external_table_task, execution_date=20240315T000000, start_date=20240326T030229, end_date=20240326T030229
[2024-03-26T03:02:29.935+0000] {standard_task_runner.py:107} ERROR - Failed to execute job 81 for task member_external_table_task (The conn_id `google_cloud_default` isn't defined; 80)
[2024-03-26T03:02:29.964+0000] {local_task_job_runner.py:234} INFO - Task exited with return code 1
[2024-03-26T03:02:29.984+0000] {taskinstance.py:3312} INFO - 0 downstream tasks scheduled from follow-on schedule check
[2024-03-26T03:27:15.045+0000] {taskinstance.py:1979} INFO - Dependencies all met for dep_context=non-requeueable deps ti=<TaskInstance: upload_historical_congress_data.member_external_table_task scheduled__2024-03-15T00:00:00+00:00 [queued]>
[2024-03-26T03:27:15.054+0000] {taskinstance.py:1979} INFO - Dependencies all met for dep_context=requeueable deps ti=<TaskInstance: upload_historical_congress_data.member_external_table_task scheduled__2024-03-15T00:00:00+00:00 [queued]>
[2024-03-26T03:27:15.055+0000] {taskinstance.py:2193} INFO - Starting attempt 2 of 3
[2024-03-26T03:27:15.063+0000] {taskinstance.py:2217} INFO - Executing <Task(BigQueryCreateExternalTableOperator): member_external_table_task> on 2024-03-15 00:00:00+00:00
[2024-03-26T03:27:15.071+0000] {standard_task_runner.py:60} INFO - Started process 93 to run task
[2024-03-26T03:27:15.077+0000] {standard_task_runner.py:87} INFO - Running: ['***', 'tasks', 'run', 'upload_historical_congress_data', 'member_external_table_task', 'scheduled__2024-03-15T00:00:00+00:00', '--job-id', '93', '--raw', '--subdir', 'DAGS_FOLDER/upload_historical_congress_data.py', '--cfg-path', '/tmp/tmpgj0zv9_6']
[2024-03-26T03:27:15.082+0000] {standard_task_runner.py:88} INFO - Job 93: Subtask member_external_table_task
[2024-03-26T03:27:15.153+0000] {task_command.py:423} INFO - Running <TaskInstance: upload_historical_congress_data.member_external_table_task scheduled__2024-03-15T00:00:00+00:00 [running]> on host cb295ecee912
[2024-03-26T03:27:15.205+0000] {taskinstance.py:2513} INFO - Exporting env vars: AIRFLOW_CTX_DAG_EMAIL='***@***.com' AIRFLOW_CTX_DAG_OWNER='***' AIRFLOW_CTX_DAG_ID='upload_historical_congress_data' AIRFLOW_CTX_TASK_ID='member_external_table_task' AIRFLOW_CTX_EXECUTION_DATE='2024-03-15T00:00:00+00:00' AIRFLOW_CTX_TRY_NUMBER='2' AIRFLOW_CTX_DAG_RUN_ID='scheduled__2024-03-15T00:00:00+00:00'
[2024-03-26T03:27:15.208+0000] {crypto.py:82} WARNING - empty cryptography key - values will not be stored encrypted.
[2024-03-26T03:27:15.210+0000] {connection.py:269} WARNING - Connection schemes (type: google_cloud_platform) shall not contain '_' according to RFC3986.
[2024-03-26T03:27:15.212+0000] {base.py:83} INFO - Using connection ID 'google_cloud_default' for task execution.
[2024-03-26T03:27:15.919+0000] {taskinstance.py:2731} ERROR - Task failed with exception
Traceback (most recent call last):
  File "/home/airflow/.local/lib/python3.8/site-packages/airflow/models/taskinstance.py", line 444, in _execute_task
    result = _execute_callable(context=context, **execute_callable_kwargs)
  File "/home/airflow/.local/lib/python3.8/site-packages/airflow/models/taskinstance.py", line 414, in _execute_callable
    return execute_callable(context=context, **execute_callable_kwargs)
  File "/home/airflow/.local/lib/python3.8/site-packages/airflow/providers/google/cloud/operators/bigquery.py", line 1783, in execute
    table = bq_hook.create_empty_table(
  File "/home/airflow/.local/lib/python3.8/site-packages/airflow/providers/google/common/hooks/base_google.py", line 485, in inner_wrapper
    return func(self, *args, **kwargs)
  File "/home/airflow/.local/lib/python3.8/site-packages/airflow/providers/google/cloud/hooks/bigquery.py", line 422, in create_empty_table
    return self.get_client(project_id=project_id, location=location).create_table(
  File "/home/airflow/.local/lib/python3.8/site-packages/google/cloud/bigquery/client.py", line 797, in create_table
    api_response = self._call_api(
  File "/home/airflow/.local/lib/python3.8/site-packages/google/cloud/bigquery/client.py", line 831, in _call_api
    return call()
  File "/home/airflow/.local/lib/python3.8/site-packages/google/api_core/retry/retry_unary.py", line 293, in retry_wrapped_func
    return retry_target(
  File "/home/airflow/.local/lib/python3.8/site-packages/google/api_core/retry/retry_unary.py", line 153, in retry_target
    _retry_error_helper(
  File "/home/airflow/.local/lib/python3.8/site-packages/google/api_core/retry/retry_base.py", line 212, in _retry_error_helper
    raise final_exc from source_exc
  File "/home/airflow/.local/lib/python3.8/site-packages/google/api_core/retry/retry_unary.py", line 144, in retry_target
    result = target()
  File "/home/airflow/.local/lib/python3.8/site-packages/google/cloud/_http/__init__.py", line 494, in api_request
    raise exceptions.from_http_response(response)
google.api_core.exceptions.NotFound: 404 POST https://bigquery.googleapis.com/bigquery/v2/projects/inbound-ship-412204/datasets/Conress/tables?prettyPrint=false: Not found: Dataset inbound-ship-412204:Conress
[2024-03-26T03:27:15.950+0000] {taskinstance.py:1149} INFO - Marking task as UP_FOR_RETRY. dag_id=upload_historical_congress_data, task_id=member_external_table_task, execution_date=20240315T000000, start_date=20240326T032715, end_date=20240326T032715
[2024-03-26T03:27:15.965+0000] {standard_task_runner.py:107} ERROR - Failed to execute job 93 for task member_external_table_task (404 POST https://bigquery.googleapis.com/bigquery/v2/projects/inbound-ship-412204/datasets/Conress/tables?prettyPrint=false: Not found: Dataset inbound-ship-412204:Conress; 93)
[2024-03-26T03:27:16.003+0000] {local_task_job_runner.py:234} INFO - Task exited with return code 1
[2024-03-26T03:27:16.023+0000] {taskinstance.py:3312} INFO - 0 downstream tasks scheduled from follow-on schedule check
[2024-03-26T03:36:14.466+0000] {taskinstance.py:1979} INFO - Dependencies all met for dep_context=non-requeueable deps ti=<TaskInstance: upload_historical_congress_data.member_external_table_task scheduled__2024-03-15T00:00:00+00:00 [queued]>
[2024-03-26T03:36:14.474+0000] {taskinstance.py:1979} INFO - Dependencies all met for dep_context=requeueable deps ti=<TaskInstance: upload_historical_congress_data.member_external_table_task scheduled__2024-03-15T00:00:00+00:00 [queued]>
[2024-03-26T03:36:14.476+0000] {taskinstance.py:2193} INFO - Starting attempt 2 of 3
[2024-03-26T03:36:14.483+0000] {taskinstance.py:2217} INFO - Executing <Task(BigQueryCreateExternalTableOperator): member_external_table_task> on 2024-03-15 00:00:00+00:00
[2024-03-26T03:36:14.491+0000] {standard_task_runner.py:60} INFO - Started process 112 to run task
[2024-03-26T03:36:14.494+0000] {standard_task_runner.py:87} INFO - Running: ['***', 'tasks', 'run', 'upload_historical_congress_data', 'member_external_table_task', 'scheduled__2024-03-15T00:00:00+00:00', '--job-id', '108', '--raw', '--subdir', 'DAGS_FOLDER/upload_historical_congress_data.py', '--cfg-path', '/tmp/tmpbtl4am00']
[2024-03-26T03:36:14.498+0000] {standard_task_runner.py:88} INFO - Job 108: Subtask member_external_table_task
[2024-03-26T03:36:14.543+0000] {task_command.py:423} INFO - Running <TaskInstance: upload_historical_congress_data.member_external_table_task scheduled__2024-03-15T00:00:00+00:00 [running]> on host 8f420781146d
[2024-03-26T03:36:14.594+0000] {taskinstance.py:2513} INFO - Exporting env vars: AIRFLOW_CTX_DAG_EMAIL='***@***.com' AIRFLOW_CTX_DAG_OWNER='***' AIRFLOW_CTX_DAG_ID='upload_historical_congress_data' AIRFLOW_CTX_TASK_ID='member_external_table_task' AIRFLOW_CTX_EXECUTION_DATE='2024-03-15T00:00:00+00:00' AIRFLOW_CTX_TRY_NUMBER='2' AIRFLOW_CTX_DAG_RUN_ID='scheduled__2024-03-15T00:00:00+00:00'
[2024-03-26T03:36:14.597+0000] {crypto.py:82} WARNING - empty cryptography key - values will not be stored encrypted.
[2024-03-26T03:36:14.598+0000] {connection.py:269} WARNING - Connection schemes (type: google_cloud_platform) shall not contain '_' according to RFC3986.
[2024-03-26T03:36:14.600+0000] {base.py:83} INFO - Using connection ID 'google_cloud_default' for task execution.
[2024-03-26T03:36:15.384+0000] {taskinstance.py:2731} ERROR - Task failed with exception
Traceback (most recent call last):
  File "/home/airflow/.local/lib/python3.8/site-packages/airflow/models/taskinstance.py", line 444, in _execute_task
    result = _execute_callable(context=context, **execute_callable_kwargs)
  File "/home/airflow/.local/lib/python3.8/site-packages/airflow/models/taskinstance.py", line 414, in _execute_callable
    return execute_callable(context=context, **execute_callable_kwargs)
  File "/home/airflow/.local/lib/python3.8/site-packages/airflow/providers/google/cloud/operators/bigquery.py", line 1783, in execute
    table = bq_hook.create_empty_table(
  File "/home/airflow/.local/lib/python3.8/site-packages/airflow/providers/google/common/hooks/base_google.py", line 485, in inner_wrapper
    return func(self, *args, **kwargs)
  File "/home/airflow/.local/lib/python3.8/site-packages/airflow/providers/google/cloud/hooks/bigquery.py", line 422, in create_empty_table
    return self.get_client(project_id=project_id, location=location).create_table(
  File "/home/airflow/.local/lib/python3.8/site-packages/google/cloud/bigquery/client.py", line 797, in create_table
    api_response = self._call_api(
  File "/home/airflow/.local/lib/python3.8/site-packages/google/cloud/bigquery/client.py", line 831, in _call_api
    return call()
  File "/home/airflow/.local/lib/python3.8/site-packages/google/api_core/retry/retry_unary.py", line 293, in retry_wrapped_func
    return retry_target(
  File "/home/airflow/.local/lib/python3.8/site-packages/google/api_core/retry/retry_unary.py", line 153, in retry_target
    _retry_error_helper(
  File "/home/airflow/.local/lib/python3.8/site-packages/google/api_core/retry/retry_base.py", line 212, in _retry_error_helper
    raise final_exc from source_exc
  File "/home/airflow/.local/lib/python3.8/site-packages/google/api_core/retry/retry_unary.py", line 144, in retry_target
    result = target()
  File "/home/airflow/.local/lib/python3.8/site-packages/google/cloud/_http/__init__.py", line 494, in api_request
    raise exceptions.from_http_response(response)
google.api_core.exceptions.BadRequest: 400 POST https://bigquery.googleapis.com/bigquery/v2/projects/inbound-ship-412204/datasets/Congress/tables?prettyPrint=false: Error while reading table: member_external_table, error message: Failed to expand table member_external_table with file pattern gs://congress_data/member/*: matched no files. File: gs://congress_data/member/*
[2024-03-26T03:36:15.405+0000] {taskinstance.py:1149} INFO - Marking task as UP_FOR_RETRY. dag_id=upload_historical_congress_data, task_id=member_external_table_task, execution_date=20240315T000000, start_date=20240326T033614, end_date=20240326T033615
[2024-03-26T03:36:15.418+0000] {standard_task_runner.py:107} ERROR - Failed to execute job 108 for task member_external_table_task (400 POST https://bigquery.googleapis.com/bigquery/v2/projects/inbound-ship-412204/datasets/Congress/tables?prettyPrint=false: Error while reading table: member_external_table, error message: Failed to expand table member_external_table with file pattern gs://congress_data/member/*: matched no files. File: gs://congress_data/member/*; 112)
[2024-03-26T03:36:15.465+0000] {local_task_job_runner.py:234} INFO - Task exited with return code 1
[2024-03-26T03:36:15.492+0000] {taskinstance.py:3312} INFO - 0 downstream tasks scheduled from follow-on schedule check
[2024-03-28T03:20:17.645+0000] {taskinstance.py:1979} INFO - Dependencies all met for dep_context=non-requeueable deps ti=<TaskInstance: upload_historical_congress_data.member_external_table_task scheduled__2024-03-15T00:00:00+00:00 [queued]>
[2024-03-28T03:20:17.653+0000] {taskinstance.py:1979} INFO - Dependencies all met for dep_context=requeueable deps ti=<TaskInstance: upload_historical_congress_data.member_external_table_task scheduled__2024-03-15T00:00:00+00:00 [queued]>
[2024-03-28T03:20:17.655+0000] {taskinstance.py:2193} INFO - Starting attempt 2 of 4
[2024-03-28T03:20:17.664+0000] {taskinstance.py:2217} INFO - Executing <Task(BigQueryCreateExternalTableOperator): member_external_table_task> on 2024-03-15 00:00:00+00:00
[2024-03-28T03:20:17.671+0000] {standard_task_runner.py:60} INFO - Started process 77 to run task
[2024-03-28T03:20:17.674+0000] {standard_task_runner.py:87} INFO - Running: ['***', 'tasks', 'run', 'upload_historical_congress_data', 'member_external_table_task', 'scheduled__2024-03-15T00:00:00+00:00', '--job-id', '140', '--raw', '--subdir', 'DAGS_FOLDER/upload_historical_congress_data.py', '--cfg-path', '/tmp/tmpsj5i_94s']
[2024-03-28T03:20:17.679+0000] {standard_task_runner.py:88} INFO - Job 140: Subtask member_external_table_task
[2024-03-28T03:20:17.730+0000] {task_command.py:423} INFO - Running <TaskInstance: upload_historical_congress_data.member_external_table_task scheduled__2024-03-15T00:00:00+00:00 [running]> on host be5d54f7fe24
[2024-03-28T03:20:17.802+0000] {taskinstance.py:2513} INFO - Exporting env vars: AIRFLOW_CTX_DAG_EMAIL='***@***.com' AIRFLOW_CTX_DAG_OWNER='***' AIRFLOW_CTX_DAG_ID='upload_historical_congress_data' AIRFLOW_CTX_TASK_ID='member_external_table_task' AIRFLOW_CTX_EXECUTION_DATE='2024-03-15T00:00:00+00:00' AIRFLOW_CTX_TRY_NUMBER='2' AIRFLOW_CTX_DAG_RUN_ID='scheduled__2024-03-15T00:00:00+00:00'
[2024-03-28T03:20:17.806+0000] {crypto.py:82} WARNING - empty cryptography key - values will not be stored encrypted.
[2024-03-28T03:20:17.807+0000] {connection.py:269} WARNING - Connection schemes (type: google_cloud_platform) shall not contain '_' according to RFC3986.
[2024-03-28T03:20:17.809+0000] {base.py:83} INFO - Using connection ID 'google_cloud_default' for task execution.
[2024-03-28T03:20:18.483+0000] {taskinstance.py:2731} ERROR - Task failed with exception
Traceback (most recent call last):
  File "/home/airflow/.local/lib/python3.8/site-packages/airflow/models/taskinstance.py", line 444, in _execute_task
    result = _execute_callable(context=context, **execute_callable_kwargs)
  File "/home/airflow/.local/lib/python3.8/site-packages/airflow/models/taskinstance.py", line 414, in _execute_callable
    return execute_callable(context=context, **execute_callable_kwargs)
  File "/home/airflow/.local/lib/python3.8/site-packages/airflow/providers/google/cloud/operators/bigquery.py", line 1783, in execute
    table = bq_hook.create_empty_table(
  File "/home/airflow/.local/lib/python3.8/site-packages/airflow/providers/google/common/hooks/base_google.py", line 485, in inner_wrapper
    return func(self, *args, **kwargs)
  File "/home/airflow/.local/lib/python3.8/site-packages/airflow/providers/google/cloud/hooks/bigquery.py", line 422, in create_empty_table
    return self.get_client(project_id=project_id, location=location).create_table(
  File "/home/airflow/.local/lib/python3.8/site-packages/google/cloud/bigquery/client.py", line 797, in create_table
    api_response = self._call_api(
  File "/home/airflow/.local/lib/python3.8/site-packages/google/cloud/bigquery/client.py", line 831, in _call_api
    return call()
  File "/home/airflow/.local/lib/python3.8/site-packages/google/api_core/retry/retry_unary.py", line 293, in retry_wrapped_func
    return retry_target(
  File "/home/airflow/.local/lib/python3.8/site-packages/google/api_core/retry/retry_unary.py", line 153, in retry_target
    _retry_error_helper(
  File "/home/airflow/.local/lib/python3.8/site-packages/google/api_core/retry/retry_base.py", line 212, in _retry_error_helper
    raise final_exc from source_exc
  File "/home/airflow/.local/lib/python3.8/site-packages/google/api_core/retry/retry_unary.py", line 144, in retry_target
    result = target()
  File "/home/airflow/.local/lib/python3.8/site-packages/google/cloud/_http/__init__.py", line 494, in api_request
    raise exceptions.from_http_response(response)
google.api_core.exceptions.BadRequest: 400 POST https://bigquery.googleapis.com/bigquery/v2/projects/inbound-ship-412204/datasets/Congress/tables?prettyPrint=false: Invalid value for type: ARRAY<STRUCT<CHAMBER STRING, ENDYEAR INT64, STARTYEAR INT64>> is not a valid value
[2024-03-28T03:20:18.513+0000] {taskinstance.py:1149} INFO - Marking task as UP_FOR_RETRY. dag_id=upload_historical_congress_data, task_id=member_external_table_task, execution_date=20240315T000000, start_date=20240328T032017, end_date=20240328T032018
[2024-03-28T03:20:18.527+0000] {standard_task_runner.py:107} ERROR - Failed to execute job 140 for task member_external_table_task (400 POST https://bigquery.googleapis.com/bigquery/v2/projects/inbound-ship-412204/datasets/Congress/tables?prettyPrint=false: Invalid value for type: ARRAY<STRUCT<CHAMBER STRING, ENDYEAR INT64, STARTYEAR INT64>> is not a valid value; 77)
[2024-03-28T03:20:18.568+0000] {local_task_job_runner.py:234} INFO - Task exited with return code 1
[2024-03-28T03:20:18.590+0000] {taskinstance.py:3312} INFO - 0 downstream tasks scheduled from follow-on schedule check
[2024-03-28T03:54:13.834+0000] {taskinstance.py:1979} INFO - Dependencies all met for dep_context=non-requeueable deps ti=<TaskInstance: upload_historical_congress_data.member_external_table_task scheduled__2024-03-15T00:00:00+00:00 [queued]>
[2024-03-28T03:54:13.843+0000] {taskinstance.py:1979} INFO - Dependencies all met for dep_context=requeueable deps ti=<TaskInstance: upload_historical_congress_data.member_external_table_task scheduled__2024-03-15T00:00:00+00:00 [queued]>
[2024-03-28T03:54:13.845+0000] {taskinstance.py:2193} INFO - Starting attempt 2 of 4
[2024-03-28T03:54:13.856+0000] {taskinstance.py:2217} INFO - Executing <Task(BigQueryCreateExternalTableOperator): member_external_table_task> on 2024-03-15 00:00:00+00:00
[2024-03-28T03:54:13.864+0000] {standard_task_runner.py:60} INFO - Started process 308 to run task
[2024-03-28T03:54:13.868+0000] {standard_task_runner.py:87} INFO - Running: ['***', 'tasks', 'run', 'upload_historical_congress_data', 'member_external_table_task', 'scheduled__2024-03-15T00:00:00+00:00', '--job-id', '166', '--raw', '--subdir', 'DAGS_FOLDER/upload_historical_congress_data.py', '--cfg-path', '/tmp/tmpjn2uuez_']
[2024-03-28T03:54:13.872+0000] {standard_task_runner.py:88} INFO - Job 166: Subtask member_external_table_task
[2024-03-28T03:54:13.927+0000] {task_command.py:423} INFO - Running <TaskInstance: upload_historical_congress_data.member_external_table_task scheduled__2024-03-15T00:00:00+00:00 [running]> on host be5d54f7fe24
[2024-03-28T03:54:13.983+0000] {taskinstance.py:2513} INFO - Exporting env vars: AIRFLOW_CTX_DAG_EMAIL='***@***.com' AIRFLOW_CTX_DAG_OWNER='***' AIRFLOW_CTX_DAG_ID='upload_historical_congress_data' AIRFLOW_CTX_TASK_ID='member_external_table_task' AIRFLOW_CTX_EXECUTION_DATE='2024-03-15T00:00:00+00:00' AIRFLOW_CTX_TRY_NUMBER='2' AIRFLOW_CTX_DAG_RUN_ID='scheduled__2024-03-15T00:00:00+00:00'
[2024-03-28T03:54:13.986+0000] {crypto.py:82} WARNING - empty cryptography key - values will not be stored encrypted.
[2024-03-28T03:54:13.988+0000] {connection.py:269} WARNING - Connection schemes (type: google_cloud_platform) shall not contain '_' according to RFC3986.
[2024-03-28T03:54:13.990+0000] {base.py:83} INFO - Using connection ID 'google_cloud_default' for task execution.
[2024-03-28T03:54:14.991+0000] {taskinstance.py:1149} INFO - Marking task as SUCCESS. dag_id=upload_historical_congress_data, task_id=member_external_table_task, execution_date=20240315T000000, start_date=20240328T035413, end_date=20240328T035414
[2024-03-28T03:54:15.015+0000] {local_task_job_runner.py:234} INFO - Task exited with return code 0
[2024-03-28T03:54:15.036+0000] {taskinstance.py:3312} INFO - 1 downstream tasks scheduled from follow-on schedule check
