[2024-03-26T03:27:50.073+0000] {taskinstance.py:1979} INFO - Dependencies all met for dep_context=non-requeueable deps ti=<TaskInstance: upload_historical_congress_data.bills_external_table_task scheduled__2024-03-15T00:00:00+00:00 [queued]>
[2024-03-26T03:27:50.089+0000] {taskinstance.py:1979} INFO - Dependencies all met for dep_context=requeueable deps ti=<TaskInstance: upload_historical_congress_data.bills_external_table_task scheduled__2024-03-15T00:00:00+00:00 [queued]>
[2024-03-26T03:27:50.093+0000] {taskinstance.py:2193} INFO - Starting attempt 2 of 3
[2024-03-26T03:27:50.109+0000] {taskinstance.py:2217} INFO - Executing <Task(BigQueryCreateExternalTableOperator): bills_external_table_task> on 2024-03-15 00:00:00+00:00
[2024-03-26T03:27:50.126+0000] {standard_task_runner.py:60} INFO - Started process 106 to run task
[2024-03-26T03:27:50.132+0000] {standard_task_runner.py:87} INFO - Running: ['***', 'tasks', 'run', 'upload_historical_congress_data', 'bills_external_table_task', 'scheduled__2024-03-15T00:00:00+00:00', '--job-id', '94', '--raw', '--subdir', 'DAGS_FOLDER/upload_historical_congress_data.py', '--cfg-path', '/tmp/tmp106vnof4']
[2024-03-26T03:27:50.140+0000] {standard_task_runner.py:88} INFO - Job 94: Subtask bills_external_table_task
[2024-03-26T03:27:50.234+0000] {task_command.py:423} INFO - Running <TaskInstance: upload_historical_congress_data.bills_external_table_task scheduled__2024-03-15T00:00:00+00:00 [running]> on host cb295ecee912
[2024-03-26T03:27:50.312+0000] {taskinstance.py:2513} INFO - Exporting env vars: AIRFLOW_CTX_DAG_EMAIL='***@***.com' AIRFLOW_CTX_DAG_OWNER='***' AIRFLOW_CTX_DAG_ID='upload_historical_congress_data' AIRFLOW_CTX_TASK_ID='bills_external_table_task' AIRFLOW_CTX_EXECUTION_DATE='2024-03-15T00:00:00+00:00' AIRFLOW_CTX_TRY_NUMBER='2' AIRFLOW_CTX_DAG_RUN_ID='scheduled__2024-03-15T00:00:00+00:00'
[2024-03-26T03:27:50.318+0000] {crypto.py:82} WARNING - empty cryptography key - values will not be stored encrypted.
[2024-03-26T03:27:50.319+0000] {connection.py:269} WARNING - Connection schemes (type: google_cloud_platform) shall not contain '_' according to RFC3986.
[2024-03-26T03:27:50.324+0000] {base.py:83} INFO - Using connection ID 'google_cloud_default' for task execution.
[2024-03-26T03:27:51.014+0000] {taskinstance.py:2731} ERROR - Task failed with exception
Traceback (most recent call last):
  File "/home/airflow/.local/lib/python3.8/site-packages/airflow/models/taskinstance.py", line 444, in _execute_task
    result = _execute_callable(context=context, **execute_callable_kwargs)
  File "/home/airflow/.local/lib/python3.8/site-packages/airflow/models/taskinstance.py", line 414, in _execute_callable
    return execute_callable(context=context, **execute_callable_kwargs)
  File "/home/airflow/.local/lib/python3.8/site-packages/airflow/providers/google/cloud/operators/bigquery.py", line 1783, in execute
    table = bq_hook.create_empty_table(
  File "/home/airflow/.local/lib/python3.8/site-packages/airflow/providers/google/common/hooks/base_google.py", line 485, in inner_wrapper
    return func(self, *args, **kwargs)
  File "/home/airflow/.local/lib/python3.8/site-packages/airflow/providers/google/cloud/hooks/bigquery.py", line 422, in create_empty_table
    return self.get_client(project_id=project_id, location=location).create_table(
  File "/home/airflow/.local/lib/python3.8/site-packages/google/cloud/bigquery/client.py", line 797, in create_table
    api_response = self._call_api(
  File "/home/airflow/.local/lib/python3.8/site-packages/google/cloud/bigquery/client.py", line 831, in _call_api
    return call()
  File "/home/airflow/.local/lib/python3.8/site-packages/google/api_core/retry/retry_unary.py", line 293, in retry_wrapped_func
    return retry_target(
  File "/home/airflow/.local/lib/python3.8/site-packages/google/api_core/retry/retry_unary.py", line 153, in retry_target
    _retry_error_helper(
  File "/home/airflow/.local/lib/python3.8/site-packages/google/api_core/retry/retry_base.py", line 212, in _retry_error_helper
    raise final_exc from source_exc
  File "/home/airflow/.local/lib/python3.8/site-packages/google/api_core/retry/retry_unary.py", line 144, in retry_target
    result = target()
  File "/home/airflow/.local/lib/python3.8/site-packages/google/cloud/_http/__init__.py", line 494, in api_request
    raise exceptions.from_http_response(response)
google.api_core.exceptions.NotFound: 404 POST https://bigquery.googleapis.com/bigquery/v2/projects/inbound-ship-412204/datasets/Conress/tables?prettyPrint=false: Not found: Dataset inbound-ship-412204:Conress
[2024-03-26T03:27:51.042+0000] {taskinstance.py:1149} INFO - Marking task as UP_FOR_RETRY. dag_id=upload_historical_congress_data, task_id=bills_external_table_task, execution_date=20240315T000000, start_date=20240326T032750, end_date=20240326T032751
[2024-03-26T03:27:51.060+0000] {standard_task_runner.py:107} ERROR - Failed to execute job 94 for task bills_external_table_task (404 POST https://bigquery.googleapis.com/bigquery/v2/projects/inbound-ship-412204/datasets/Conress/tables?prettyPrint=false: Not found: Dataset inbound-ship-412204:Conress; 106)
[2024-03-26T03:27:51.108+0000] {local_task_job_runner.py:234} INFO - Task exited with return code 1
[2024-03-26T03:27:51.131+0000] {taskinstance.py:3312} INFO - 0 downstream tasks scheduled from follow-on schedule check
[2024-03-28T03:24:32.819+0000] {taskinstance.py:1979} INFO - Dependencies all met for dep_context=non-requeueable deps ti=<TaskInstance: upload_historical_congress_data.bills_external_table_task scheduled__2024-03-15T00:00:00+00:00 [queued]>
[2024-03-28T03:24:32.828+0000] {taskinstance.py:1979} INFO - Dependencies all met for dep_context=requeueable deps ti=<TaskInstance: upload_historical_congress_data.bills_external_table_task scheduled__2024-03-15T00:00:00+00:00 [queued]>
[2024-03-28T03:24:32.830+0000] {taskinstance.py:2193} INFO - Starting attempt 2 of 3
[2024-03-28T03:24:32.839+0000] {taskinstance.py:2217} INFO - Executing <Task(BigQueryCreateExternalTableOperator): bills_external_table_task> on 2024-03-15 00:00:00+00:00
[2024-03-28T03:24:32.847+0000] {standard_task_runner.py:60} INFO - Started process 164 to run task
[2024-03-28T03:24:32.864+0000] {standard_task_runner.py:87} INFO - Running: ['***', 'tasks', 'run', 'upload_historical_congress_data', 'bills_external_table_task', 'scheduled__2024-03-15T00:00:00+00:00', '--job-id', '148', '--raw', '--subdir', 'DAGS_FOLDER/upload_historical_congress_data.py', '--cfg-path', '/tmp/tmpmy8zlnkb']
[2024-03-28T03:24:32.872+0000] {standard_task_runner.py:88} INFO - Job 148: Subtask bills_external_table_task
[2024-03-28T03:24:32.924+0000] {task_command.py:423} INFO - Running <TaskInstance: upload_historical_congress_data.bills_external_table_task scheduled__2024-03-15T00:00:00+00:00 [running]> on host be5d54f7fe24
[2024-03-28T03:24:32.983+0000] {taskinstance.py:2513} INFO - Exporting env vars: AIRFLOW_CTX_DAG_EMAIL='***@***.com' AIRFLOW_CTX_DAG_OWNER='***' AIRFLOW_CTX_DAG_ID='upload_historical_congress_data' AIRFLOW_CTX_TASK_ID='bills_external_table_task' AIRFLOW_CTX_EXECUTION_DATE='2024-03-15T00:00:00+00:00' AIRFLOW_CTX_TRY_NUMBER='2' AIRFLOW_CTX_DAG_RUN_ID='scheduled__2024-03-15T00:00:00+00:00'
[2024-03-28T03:24:32.987+0000] {crypto.py:82} WARNING - empty cryptography key - values will not be stored encrypted.
[2024-03-28T03:24:32.990+0000] {connection.py:269} WARNING - Connection schemes (type: google_cloud_platform) shall not contain '_' according to RFC3986.
[2024-03-28T03:24:32.992+0000] {base.py:83} INFO - Using connection ID 'google_cloud_default' for task execution.
[2024-03-28T03:24:33.590+0000] {taskinstance.py:2731} ERROR - Task failed with exception
Traceback (most recent call last):
  File "/home/airflow/.local/lib/python3.8/site-packages/airflow/models/taskinstance.py", line 444, in _execute_task
    result = _execute_callable(context=context, **execute_callable_kwargs)
  File "/home/airflow/.local/lib/python3.8/site-packages/airflow/models/taskinstance.py", line 414, in _execute_callable
    return execute_callable(context=context, **execute_callable_kwargs)
  File "/home/airflow/.local/lib/python3.8/site-packages/airflow/providers/google/cloud/operators/bigquery.py", line 1783, in execute
    table = bq_hook.create_empty_table(
  File "/home/airflow/.local/lib/python3.8/site-packages/airflow/providers/google/common/hooks/base_google.py", line 485, in inner_wrapper
    return func(self, *args, **kwargs)
  File "/home/airflow/.local/lib/python3.8/site-packages/airflow/providers/google/cloud/hooks/bigquery.py", line 422, in create_empty_table
    return self.get_client(project_id=project_id, location=location).create_table(
  File "/home/airflow/.local/lib/python3.8/site-packages/google/cloud/bigquery/client.py", line 797, in create_table
    api_response = self._call_api(
  File "/home/airflow/.local/lib/python3.8/site-packages/google/cloud/bigquery/client.py", line 831, in _call_api
    return call()
  File "/home/airflow/.local/lib/python3.8/site-packages/google/api_core/retry/retry_unary.py", line 293, in retry_wrapped_func
    return retry_target(
  File "/home/airflow/.local/lib/python3.8/site-packages/google/api_core/retry/retry_unary.py", line 153, in retry_target
    _retry_error_helper(
  File "/home/airflow/.local/lib/python3.8/site-packages/google/api_core/retry/retry_base.py", line 212, in _retry_error_helper
    raise final_exc from source_exc
  File "/home/airflow/.local/lib/python3.8/site-packages/google/api_core/retry/retry_unary.py", line 144, in retry_target
    result = target()
  File "/home/airflow/.local/lib/python3.8/site-packages/google/cloud/_http/__init__.py", line 494, in api_request
    raise exceptions.from_http_response(response)
google.api_core.exceptions.BadRequest: 400 POST https://bigquery.googleapis.com/bigquery/v2/projects/inbound-ship-412204/datasets/Congress/tables?prettyPrint=false: Invalid value for type: STRUCT<ACTIONDATE DATE, TEXT STRING> is not a valid value
[2024-03-28T03:24:33.614+0000] {taskinstance.py:1149} INFO - Marking task as UP_FOR_RETRY. dag_id=upload_historical_congress_data, task_id=bills_external_table_task, execution_date=20240315T000000, start_date=20240328T032432, end_date=20240328T032433
[2024-03-28T03:24:33.628+0000] {standard_task_runner.py:107} ERROR - Failed to execute job 148 for task bills_external_table_task (400 POST https://bigquery.googleapis.com/bigquery/v2/projects/inbound-ship-412204/datasets/Congress/tables?prettyPrint=false: Invalid value for type: STRUCT<ACTIONDATE DATE, TEXT STRING> is not a valid value; 164)
[2024-03-28T03:24:33.652+0000] {local_task_job_runner.py:234} INFO - Task exited with return code 1
[2024-03-28T03:24:33.681+0000] {taskinstance.py:3312} INFO - 0 downstream tasks scheduled from follow-on schedule check
