[2024-05-02T03:55:45.348+0000] {taskinstance.py:1979} INFO - Dependencies all met for dep_context=non-requeueable deps ti=<TaskInstance: upload_congress_data.get_members_data scheduled__2024-03-15T00:00:00+00:00 [queued]>
[2024-05-02T03:55:45.360+0000] {taskinstance.py:1979} INFO - Dependencies all met for dep_context=requeueable deps ti=<TaskInstance: upload_congress_data.get_members_data scheduled__2024-03-15T00:00:00+00:00 [queued]>
[2024-05-02T03:55:45.361+0000] {taskinstance.py:2193} INFO - Starting attempt 2 of 3
[2024-05-02T03:55:45.373+0000] {taskinstance.py:2217} INFO - Executing <Task(PythonOperator): get_members_data> on 2024-03-15 00:00:00+00:00
[2024-05-02T03:55:45.385+0000] {standard_task_runner.py:60} INFO - Started process 90 to run task
[2024-05-02T03:55:45.398+0000] {standard_task_runner.py:87} INFO - Running: ['***', 'tasks', 'run', 'upload_congress_data', 'get_members_data', 'scheduled__2024-03-15T00:00:00+00:00', '--job-id', '6', '--raw', '--subdir', 'DAGS_FOLDER/upload_congress_data.py', '--cfg-path', '/tmp/tmpteak0qnb']
[2024-05-02T03:55:45.415+0000] {standard_task_runner.py:88} INFO - Job 6: Subtask get_members_data
[2024-05-02T03:55:45.505+0000] {task_command.py:423} INFO - Running <TaskInstance: upload_congress_data.get_members_data scheduled__2024-03-15T00:00:00+00:00 [running]> on host 9a9189dcfea1
[2024-05-02T03:55:45.597+0000] {taskinstance.py:2513} INFO - Exporting env vars: AIRFLOW_CTX_DAG_EMAIL='***@***.com' AIRFLOW_CTX_DAG_OWNER='***' AIRFLOW_CTX_DAG_ID='upload_congress_data' AIRFLOW_CTX_TASK_ID='get_members_data' AIRFLOW_CTX_EXECUTION_DATE='2024-03-15T00:00:00+00:00' AIRFLOW_CTX_TRY_NUMBER='2' AIRFLOW_CTX_DAG_RUN_ID='scheduled__2024-03-15T00:00:00+00:00'
[2024-05-02T03:55:45.614+0000] {get_data.py:160} INFO - Max records passed as None
[2024-05-02T03:55:45.620+0000] {get_data.py:205} INFO - executing API call for https://api.congress.gov/v3/member?format=json&fromDateTime=2023-01-01T00:00:00Z&toDateTime=2024-03-15T00:00:00Z&offset=0&limit=250&api_key=WNue8kCDCOIlewAsULgnN8j6SqSgAZjE2sYbPsBb
[2024-05-02T03:55:46.663+0000] {get_data.py:167} INFO - About to start fetching 656 records
[2024-05-02T03:55:46.664+0000] {get_data.py:205} INFO - executing API call for https://api.congress.gov/v3/member?format=json&fromDateTime=2023-01-01T00:00:00Z&toDateTime=2024-03-15T00:00:00Z&offset=0&limit=250&api_key=WNue8kCDCOIlewAsULgnN8j6SqSgAZjE2sYbPsBb
[2024-05-02T03:55:47.916+0000] {taskinstance.py:2731} ERROR - Task failed with exception
Traceback (most recent call last):
  File "/home/airflow/.local/lib/python3.11/site-packages/pandas/core/indexes/base.py", line 3791, in get_loc
    return self._engine.get_loc(casted_key)
           ^^^^^^^^^^^^^^^^^^^^^^^^^^^^^^^^
  File "index.pyx", line 152, in pandas._libs.index.IndexEngine.get_loc
  File "index.pyx", line 181, in pandas._libs.index.IndexEngine.get_loc
  File "pandas/_libs/hashtable_class_helper.pxi", line 7080, in pandas._libs.hashtable.PyObjectHashTable.get_item
  File "pandas/_libs/hashtable_class_helper.pxi", line 7088, in pandas._libs.hashtable.PyObjectHashTable.get_item
KeyError: 0

The above exception was the direct cause of the following exception:

Traceback (most recent call last):
  File "/home/airflow/.local/lib/python3.11/site-packages/airflow/models/taskinstance.py", line 444, in _execute_task
    result = _execute_callable(context=context, **execute_callable_kwargs)
             ^^^^^^^^^^^^^^^^^^^^^^^^^^^^^^^^^^^^^^^^^^^^^^^^^^^^^^^^^^^^^
  File "/home/airflow/.local/lib/python3.11/site-packages/airflow/models/taskinstance.py", line 414, in _execute_callable
    return execute_callable(context=context, **execute_callable_kwargs)
           ^^^^^^^^^^^^^^^^^^^^^^^^^^^^^^^^^^^^^^^^^^^^^^^^^^^^^^^^^^^^
  File "/home/airflow/.local/lib/python3.11/site-packages/airflow/operators/python.py", line 200, in execute
    return_value = self.execute_callable()
                   ^^^^^^^^^^^^^^^^^^^^^^^
  File "/home/airflow/.local/lib/python3.11/site-packages/airflow/operators/python.py", line 217, in execute_callable
    return self.python_callable(*self.op_args, **self.op_kwargs)
           ^^^^^^^^^^^^^^^^^^^^^^^^^^^^^^^^^^^^^^^^^^^^^^^^^^^^^
  File "/opt/airflow/dags/scripts/python/get_data.py", line 181, in get_members
    f.write(members_df[row].to_json() + "\n")
            ~~~~~~~~~~^^^^^
  File "/home/airflow/.local/lib/python3.11/site-packages/pandas/core/frame.py", line 3893, in __getitem__
    indexer = self.columns.get_loc(key)
              ^^^^^^^^^^^^^^^^^^^^^^^^^
  File "/home/airflow/.local/lib/python3.11/site-packages/pandas/core/indexes/base.py", line 3798, in get_loc
    raise KeyError(key) from err
KeyError: 0
[2024-05-02T03:55:47.940+0000] {taskinstance.py:1149} INFO - Marking task as UP_FOR_RETRY. dag_id=upload_congress_data, task_id=get_members_data, execution_date=20240315T000000, start_date=20240502T035545, end_date=20240502T035547
[2024-05-02T03:55:47.959+0000] {standard_task_runner.py:107} ERROR - Failed to execute job 6 for task get_members_data (0; 90)
[2024-05-02T03:55:47.990+0000] {local_task_job_runner.py:234} INFO - Task exited with return code 1
[2024-05-02T03:55:48.020+0000] {taskinstance.py:3312} INFO - 0 downstream tasks scheduled from follow-on schedule check
[2024-06-21T03:11:23.595+0000] {taskinstance.py:1979} INFO - Dependencies all met for dep_context=non-requeueable deps ti=<TaskInstance: upload_congress_data.get_members_data scheduled__2024-03-15T00:00:00+00:00 [queued]>
[2024-06-21T03:11:23.604+0000] {taskinstance.py:1979} INFO - Dependencies all met for dep_context=requeueable deps ti=<TaskInstance: upload_congress_data.get_members_data scheduled__2024-03-15T00:00:00+00:00 [queued]>
[2024-06-21T03:11:23.605+0000] {taskinstance.py:2193} INFO - Starting attempt 2 of 3
[2024-06-21T03:11:23.622+0000] {taskinstance.py:2217} INFO - Executing <Task(PythonOperator): get_members_data> on 2024-03-15 00:00:00+00:00
[2024-06-21T03:11:23.630+0000] {standard_task_runner.py:60} INFO - Started process 91 to run task
[2024-06-21T03:11:23.639+0000] {standard_task_runner.py:87} INFO - Running: ['***', 'tasks', 'run', 'upload_congress_data', 'get_members_data', 'scheduled__2024-03-15T00:00:00+00:00', '--job-id', '6', '--raw', '--subdir', 'DAGS_FOLDER/upload_congress_data.py', '--cfg-path', '/tmp/tmp_jib_e6v']
[2024-06-21T03:11:23.650+0000] {standard_task_runner.py:88} INFO - Job 6: Subtask get_members_data
[2024-06-21T03:11:23.815+0000] {task_command.py:423} INFO - Running <TaskInstance: upload_congress_data.get_members_data scheduled__2024-03-15T00:00:00+00:00 [running]> on host e69b8c0a2a30
[2024-06-21T03:11:23.968+0000] {taskinstance.py:2513} INFO - Exporting env vars: AIRFLOW_CTX_DAG_EMAIL='***@***.com' AIRFLOW_CTX_DAG_OWNER='***' AIRFLOW_CTX_DAG_ID='upload_congress_data' AIRFLOW_CTX_TASK_ID='get_members_data' AIRFLOW_CTX_EXECUTION_DATE='2024-03-15T00:00:00+00:00' AIRFLOW_CTX_TRY_NUMBER='2' AIRFLOW_CTX_DAG_RUN_ID='scheduled__2024-03-15T00:00:00+00:00'
[2024-06-21T03:11:23.972+0000] {taskinstance.py:2731} ERROR - Task failed with exception
Traceback (most recent call last):
  File "/home/airflow/.local/lib/python3.11/site-packages/airflow/models/taskinstance.py", line 444, in _execute_task
    result = _execute_callable(context=context, **execute_callable_kwargs)
             ^^^^^^^^^^^^^^^^^^^^^^^^^^^^^^^^^^^^^^^^^^^^^^^^^^^^^^^^^^^^^
  File "/home/airflow/.local/lib/python3.11/site-packages/airflow/models/taskinstance.py", line 414, in _execute_callable
    return execute_callable(context=context, **execute_callable_kwargs)
           ^^^^^^^^^^^^^^^^^^^^^^^^^^^^^^^^^^^^^^^^^^^^^^^^^^^^^^^^^^^^
  File "/home/airflow/.local/lib/python3.11/site-packages/airflow/operators/python.py", line 200, in execute
    return_value = self.execute_callable()
                   ^^^^^^^^^^^^^^^^^^^^^^^
  File "/home/airflow/.local/lib/python3.11/site-packages/airflow/operators/python.py", line 217, in execute_callable
    return self.python_callable(*self.op_args, **self.op_kwargs)
           ^^^^^^^^^^^^^^^^^^^^^^^^^^^^^^^^^^^^^^^^^^^^^^^^^^^^^
  File "/opt/airflow/dags/scripts/python/get_data.py", line 152, in get_members
    params['end_date'] = ti.xcom_pull(task_ids='format_execution_date_task', key='formatted_end_date')
                         ^^
NameError: name 'ti' is not defined
[2024-06-21T03:11:23.990+0000] {taskinstance.py:1149} INFO - Marking task as UP_FOR_RETRY. dag_id=upload_congress_data, task_id=get_members_data, execution_date=20240315T000000, start_date=20240621T031123, end_date=20240621T031123
[2024-06-21T03:11:24.012+0000] {standard_task_runner.py:107} ERROR - Failed to execute job 6 for task get_members_data (name 'ti' is not defined; 91)
[2024-06-21T03:11:24.057+0000] {local_task_job_runner.py:234} INFO - Task exited with return code 1
[2024-06-21T03:11:24.089+0000] {taskinstance.py:3312} INFO - 0 downstream tasks scheduled from follow-on schedule check
