[2024-05-02T03:56:50.508+0000] {taskinstance.py:1979} INFO - Dependencies all met for dep_context=non-requeueable deps ti=<TaskInstance: upload_congress_data.get_members_data scheduled__2024-03-15T00:00:00+00:00 [queued]>
[2024-05-02T03:56:50.525+0000] {taskinstance.py:1979} INFO - Dependencies all met for dep_context=requeueable deps ti=<TaskInstance: upload_congress_data.get_members_data scheduled__2024-03-15T00:00:00+00:00 [queued]>
[2024-05-02T03:56:50.527+0000] {taskinstance.py:2193} INFO - Starting attempt 3 of 3
[2024-05-02T03:56:50.538+0000] {taskinstance.py:2217} INFO - Executing <Task(PythonOperator): get_members_data> on 2024-03-15 00:00:00+00:00
[2024-05-02T03:56:50.549+0000] {standard_task_runner.py:60} INFO - Started process 136 to run task
[2024-05-02T03:56:50.554+0000] {standard_task_runner.py:87} INFO - Running: ['***', 'tasks', 'run', 'upload_congress_data', 'get_members_data', 'scheduled__2024-03-15T00:00:00+00:00', '--job-id', '8', '--raw', '--subdir', 'DAGS_FOLDER/upload_congress_data.py', '--cfg-path', '/tmp/tmp0gbe9rf1']
[2024-05-02T03:56:50.560+0000] {standard_task_runner.py:88} INFO - Job 8: Subtask get_members_data
[2024-05-02T03:56:50.611+0000] {task_command.py:423} INFO - Running <TaskInstance: upload_congress_data.get_members_data scheduled__2024-03-15T00:00:00+00:00 [running]> on host 9a9189dcfea1
[2024-05-02T03:56:50.680+0000] {taskinstance.py:2513} INFO - Exporting env vars: AIRFLOW_CTX_DAG_EMAIL='***@***.com' AIRFLOW_CTX_DAG_OWNER='***' AIRFLOW_CTX_DAG_ID='upload_congress_data' AIRFLOW_CTX_TASK_ID='get_members_data' AIRFLOW_CTX_EXECUTION_DATE='2024-03-15T00:00:00+00:00' AIRFLOW_CTX_TRY_NUMBER='3' AIRFLOW_CTX_DAG_RUN_ID='scheduled__2024-03-15T00:00:00+00:00'
[2024-05-02T03:56:50.686+0000] {get_data.py:160} INFO - Max records passed as None
[2024-05-02T03:56:50.687+0000] {get_data.py:205} INFO - executing API call for https://api.congress.gov/v3/member?format=json&fromDateTime=2023-01-01T00:00:00Z&toDateTime=2024-03-15T00:00:00Z&offset=0&limit=250&api_key=WNue8kCDCOIlewAsULgnN8j6SqSgAZjE2sYbPsBb
[2024-05-02T03:56:55.100+0000] {get_data.py:167} INFO - About to start fetching 656 records
[2024-05-02T03:56:55.104+0000] {get_data.py:205} INFO - executing API call for https://api.congress.gov/v3/member?format=json&fromDateTime=2023-01-01T00:00:00Z&toDateTime=2024-03-15T00:00:00Z&offset=0&limit=250&api_key=WNue8kCDCOIlewAsULgnN8j6SqSgAZjE2sYbPsBb
[2024-05-02T03:56:56.637+0000] {taskinstance.py:2731} ERROR - Task failed with exception
Traceback (most recent call last):
  File "/home/airflow/.local/lib/python3.11/site-packages/pandas/core/indexes/base.py", line 3791, in get_loc
    return self._engine.get_loc(casted_key)
           ^^^^^^^^^^^^^^^^^^^^^^^^^^^^^^^^
  File "index.pyx", line 152, in pandas._libs.index.IndexEngine.get_loc
  File "index.pyx", line 181, in pandas._libs.index.IndexEngine.get_loc
  File "pandas/_libs/hashtable_class_helper.pxi", line 7080, in pandas._libs.hashtable.PyObjectHashTable.get_item
  File "pandas/_libs/hashtable_class_helper.pxi", line 7088, in pandas._libs.hashtable.PyObjectHashTable.get_item
KeyError: 0

The above exception was the direct cause of the following exception:

Traceback (most recent call last):
  File "/home/airflow/.local/lib/python3.11/site-packages/airflow/models/taskinstance.py", line 444, in _execute_task
    result = _execute_callable(context=context, **execute_callable_kwargs)
             ^^^^^^^^^^^^^^^^^^^^^^^^^^^^^^^^^^^^^^^^^^^^^^^^^^^^^^^^^^^^^
  File "/home/airflow/.local/lib/python3.11/site-packages/airflow/models/taskinstance.py", line 414, in _execute_callable
    return execute_callable(context=context, **execute_callable_kwargs)
           ^^^^^^^^^^^^^^^^^^^^^^^^^^^^^^^^^^^^^^^^^^^^^^^^^^^^^^^^^^^^
  File "/home/airflow/.local/lib/python3.11/site-packages/airflow/operators/python.py", line 200, in execute
    return_value = self.execute_callable()
                   ^^^^^^^^^^^^^^^^^^^^^^^
  File "/home/airflow/.local/lib/python3.11/site-packages/airflow/operators/python.py", line 217, in execute_callable
    return self.python_callable(*self.op_args, **self.op_kwargs)
           ^^^^^^^^^^^^^^^^^^^^^^^^^^^^^^^^^^^^^^^^^^^^^^^^^^^^^
  File "/opt/airflow/dags/scripts/python/get_data.py", line 181, in get_members
    f.write(members_df[row].to_json() + "\n")
            ~~~~~~~~~~^^^^^
  File "/home/airflow/.local/lib/python3.11/site-packages/pandas/core/frame.py", line 3893, in __getitem__
    indexer = self.columns.get_loc(key)
              ^^^^^^^^^^^^^^^^^^^^^^^^^
  File "/home/airflow/.local/lib/python3.11/site-packages/pandas/core/indexes/base.py", line 3798, in get_loc
    raise KeyError(key) from err
KeyError: 0
[2024-05-02T03:56:56.663+0000] {taskinstance.py:1149} INFO - Marking task as FAILED. dag_id=upload_congress_data, task_id=get_members_data, execution_date=20240315T000000, start_date=20240502T035650, end_date=20240502T035656
[2024-05-02T03:56:56.682+0000] {standard_task_runner.py:107} ERROR - Failed to execute job 8 for task get_members_data (0; 136)
[2024-05-02T03:56:56.739+0000] {local_task_job_runner.py:234} INFO - Task exited with return code 1
[2024-05-02T03:56:56.763+0000] {taskinstance.py:3312} INFO - 0 downstream tasks scheduled from follow-on schedule check
