[2024-04-14T20:49:49.386+0000] {task_context_logger.py:104} ERROR - Executor reports task instance <TaskInstance: upload_congress_data.format_execution_date_task scheduled__2024-03-15T00:00:00+00:00 [queued]> finished (failed) although the task says it's queued. (Info: None) Was the task killed externally?
